Workbook

Sheet Doc Info
B1: Review
B3: Review Log
G4: Ref. No.: BSB-QA-FWCMS-153-CRD-V1.0
B5: Project Name | D5: FWCMS Tech Refresh - 34384
B7: Document Information
B8: Sl # | C8: Date | D8: Updated By | E8: Update Summary | F8: Reviewed By | G8: Reviewed Date
B9: 1 | C9: 46148 | D9: Faisal | E9: Draft TC
B10: 2 | C10: 46153 | D10: Qina | E10: Update TC
B11: 3
B12: 4
B13: 5

Sheet Progress
A1: Module | B1: Total | C1: Passed | D1: Failed | E1: Blocked | F1: In Progress | G1: Not Executed | H1: Pass Completion (%) | I1: Total Test Completion (%)
A2: Mobile Responsive 1.0 | B2: =SUM(C2:G2) -> 348 | C2: =SUM('Mobile Responsive 1.0'!R1) -> 0 | D2: =SUM('Mobile Responsive 1.0'!S1) -> 0 | E2: =SUM('Mobile Responsive 1.0'!V1) -> 0 | F2: =SUM('Mobile Responsive 1.0'!U1) -> 0 | G2: =SUM('Mobile Responsive 1.0'!T1) -> 348 | H2: =C2/B2 -> 0 | I2: =(C2+D2)/B2 -> 0
A3: Mobile Responsive 1.1 | B3: =SUM(C3:G3) -> 306 | C3: =SUM('Mobile Responsive 1.1'!S3) -> 17 | D3: =SUM('Mobile Responsive 1.1'!T3) -> 19 | E3: =SUM('Mobile Responsive 1.1'!W3) -> 0 | F3: =SUM('Mobile Responsive 1.1'!V3) -> 0 | G3: =SUM('Mobile Responsive 1.1'!U1) -> 270 | H3: =C3/B3 -> 0.055555556 | I3: =(C3+D3+E3)/B3 -> 0.11764706
A4: TOTAL | B4: =SUM(B2:B3) -> 654 | C4: =SUM(C2:C3) -> 17 | D4: =SUM(D2:D3) -> 19 | E4: =SUM(E2:E3) -> 0 | F4: =SUM(F2:F3) -> 0 | G4: =SUM(G2:G3) -> 618 | H4: =C4/B4 -> 0.025993884 | I4: =(C4+D4)/B4 -> 0.055045872

Sheet Mobile Responsive 1.0
A1: Case ID | B1: Redmine User Story | C1: Tracker | D1: Features | E1: Scenario | F1: Pre Condition | G1: Case | H1: Steps | I1: Test Data | J1: Expected Result | K1: Result Browser | N1: Result | O1: Redmine Defect | P1: Additional/Comments/Issues | Q1: QA PIC | R1: =SUM(R2:R331) -> 0 | S1: =SUM(S2:S331) -> 0 | T1: =SUM(T2:T331) -> 348 | U1: =SUM(U2:U331) -> 0 | V1: =SUM(V2:V331) -> 0
K2: Safari | L2: Chrome | M2: Edge
A3: Iphone | R3: =COUNTIF($N4:N90,"PASS") -> 0 | S3: =COUNTIF($N4:N90,"FAIL") -> 0 | T3: =COUNTBLANK(N4:N90) -> 87 | U3: =COUNTIF($N4:N90,"IN PROGRESS") -> 0 | V3: =COUNTIF($N4:N90,"BLOCKED") -> 0
A4: TC.TR.MRes0.001 | D4: IDM | E4: New User Registration | G4: Verify All Fields | J4: Successfully search as per criteria selected | M4: N/A | Q4: YHUVAN
A5: TC.TR.MRes0.002 | G5: Verify All Mandatory Error Message | J5: Data displayed list should be filtered according to selected criteria | M5: N/A | Q5: YHUVAN
A6: TC.TR.MRes0.003 | G6: Reset button | J6: All fields should be cleared | M6: N/A | Q6: YHUVAN
A7: TC.TR.MRes0.004 | G7: OTP button | J7: All fields should be cleared | M7: N/A | Q7: YHUVAN
A8: TC.TR.MRes0.005 | G8: Hantar Button | J8: Successfully update application | M8: N/A | Q8: YHUVAN
A9: TC.TR.MRes0.006 | G9: Kembali ke Log Masuk | J9: Success submit application and display success message | M9: N/A | Q9: YHUVAN
A10: TC.TR.MRes0.007 | E10: Endorse User Registration | G10: Verify Table listing result | J10: Data displayed list should be filtered according to selected criteria | M10: N/A | Q10: YHUVAN
A11: TC.TR.MRes0.008 | G11: Search Record list | J11: Successfully search as per criteria selected | M11: N/A | Q11: YHUVAN
A12: TC.TR.MRes0.009 | G12: View Profile | J12: Successfully update application | M12: N/A | Q12: YHUVAN
A13: TC.TR.MRes0.010 | G13: Claim Record | J13: Successfully download Borang F | M13: N/A | Q13: YHUVAN
A14: TC.TR.MRes0.011 | G14: Release Record | J14: Success submit application and display success message | M14: N/A | Q14: YHUVAN
A15: TC.TR.MRes0.012 | G15: Update Record | J15: Successfully update user registration | Q15: YHUVAN
A16: TC.TR.MRes0.013 | G16: Hantar Button | J16: Successfully submit application | Q16: YHUVAN
A17: TC.TR.MRes0.014 | G17: Kembali button | J17: system redirect to previous page | Q17: YHUVAN
A18: TC.TR.MRes0.015 | E18: Approve User Registration | G18: Verify Table listing result | J18: Data displayed list should be filtered according to selected criteria | M18: N/A | Q18: YHUVAN
A19: TC.TR.MRes0.016 | G19: Search Record list | J19: Successfully search as per criteria selected | M19: N/A | Q19: YHUVAN
A20: TC.TR.MRes0.017 | G20: View Profile | J20: Successfully update application | M20: N/A | Q20: YHUVAN
A21: TC.TR.MRes0.018 | G21: Claim Record | J21: Successfully download Borang F | M21: N/A | Q21: YHUVAN
A22: TC.TR.MRes0.019 | G22: Release Record | J22: Success submit application and display success message | M22: N/A | Q22: YHUVAN
A23: TC.TR.MRes0.020 | G23: Update Record | J23: Successfully update user registration | Q23: YHUVAN
A24: TC.TR.MRes0.021 | G24: Hantar Button | J24: Successfully submit application | Q24: YHUVAN
A25: TC.TR.MRes0.022 | G25: Kembali button | J25: system redirect to previous page | Q25: YHUVAN
A26: TC.TR.MRes0.023 | E26: Update Profile | G26: Verify Table listing result | J26: Data displayed list should be filtered according to selected criteria | M26: N/A | Q26: YHUVAN
A27: TC.TR.MRes0.024 | G27: Search Record list | J27: Successfully search as per criteria selected | M27: N/A | Q27: YHUVAN
A28: TC.TR.MRes0.025 | G28: Update Profile | J28: Successfully update application | M28: N/A | Q28: YHUVAN
A29: TC.TR.MRes0.026 | G29: Verify All Fields | J29: Successfully download Borang F | M29: N/A | Q29: YHUVAN
A30: TC.TR.MRes0.027 | G30: Verify All Mandatory Error Message | J30: Success submit application and display success message | M30: N/A | Q30: YHUVAN
A31: TC.TR.MRes0.028 | G31: Nyahakftif | Q31: YHUVAN
A32: TC.TR.MRes0.029 | G32: Tetapkan Semula button | J32: All fields should be cleared | Q32: YHUVAN
A33: TC.TR.MRes0.030 | G33: Kembali button | Q33: YHUVAN
A34: TC.TR.MRes0.031 | D34: Pre-Quota Application | E34: Verify Document | G34: Verify Table listing result | J34: Data displayed list should be filtered according to selected criteria | M34: N/A
A35: TC.TR.MRes0.032 | G35: Search Criteria | J35: Successfully search as per criteria selected | M35: N/A
A36: TC.TR.MRes0.033 | G36: Verify Application Details | J36: Data display as expected | M36: N/A
A37: TC.TR.MRes0.034 | G37: Approved | J37: Data displayed list should be filtered according to selected criteria
A38: TC.TR.MRes0.035 | G38: Returned | J38: Successfully search as per criteria selected
A39: TC.TR.MRes0.036 | G39: Rejected | J39: Successfully reject document and system display reject message
A40: TC.TR.MRes0.037 | E40: AKS Recomendation | G40: Verify Table listing result | J40: Data displayed list should be filtered according to selected criteria | M40: N/A
...

Sheet Mobile Responsive 1.1
A1: Case ID | B1: Redmine User Story | C1: Tracker | D1: Features | E1: Scenario | F1: Pre Condition | G1: Case | H1: Complexity | I1: Steps | J1: Test Data | K1: Expected Result | L1: Result Browser | O1: Result | P1: Redmine Defect | Q1: Additional/Comments/Issues | R1: QA PIC | S1: =SUM(S3,S81,S160,S239) -> 22 | T1: =SUM(T3,T81,T160,T239) -> 19 | U1: =SUM(U3,U81,U160,U239) -> 270 | V1: =SUM(V3:V239) -> 0 | W1: =SUM(W3:W239) -> 0
L2: Safari (V....) | M2: Chrome (V...) | N2: Edge (V...)
A3: Iphone | S3: =COUNTIF($O4:O80,"PASS") -> 17 | T3: =COUNTIF($O4:O80,"FAIL") -> 19 | U3: =COUNTBLANK(O4:O80) -> 41 | V3: =COUNTIF($O4:O80,"IN PROGRESS") -> 0 | W3: =COUNTIF($O4:O80,"BLOCKED") -> 0
A4: TC.TR.MRes.001 | D4: Landing Page | E4: Homepage | F4: User logged in | G4: Login | H4: L | I4: Verify user can login with valid credentials | K4: Following must be correct : a. Spelling b. Font (Standard) c. Color (Standard) d. Translation (Locale) | L4: PASS | M4: PASS | N4: N/A | O4: PASS | R4: YHUVAN
A5: TC.TR.MRes.002 | G5: Verify Menu | H5: L | I5: Verify menu is displayed after login | K5: All labels / fields are properly aligned | L5: PASS | M5: PASS | N5: N/A | O5: PASS | R5: YHUVAN
A6: TC.TR.MRes.003 | F6: User is logged in | G6: Verify the "Lihat Status" button is displayed and clickable | H6: L | I6: 1. Navigate to Home Page 2. Locate "Lihat Status" button 3. Click the button | K6: User is navigated to correct status page with relevant data | L6: PASS | M6: PASS | N6: N/A | O6: PASS | R6: YHUVAN
A7: TC.TR.MRes.004 | F7: Notifications exist | G7: Verify notification log is displayed at Aktiviti Terkini | H7: M | I7: 1. Navigate to Home Page 2. Verify notification Aktiviti Terkini | K7: Notification history list is visible | L7: PASS | M7: PASS | N7: N/A | O7: PASS | R7: YHUVAN
A8: TC.TR.MRes.005 | F8: User has activity history | G8: Verify latest activity remarks are displayed at Pemberitahuan | H8: M | I8: 1. Navigate to Home Page 2. Verify latest oemberitahuan | K8: Latest remarks appear in correct order (most recent first) | L8: PASS | M8: PASS | N8: N/A | O8: PASS | R8: YHUVAN
A9: TC.TR.MRes.006 | D9: eComplaint | E9: Verify eComplaint | G9: Search complaint list | H9: L | K9: Successfully search as per criteria selected | L9: FAIL | N9: N/A | O9: FAIL | P9: 38485 | Q9: Complaint date not display once select specific date | R9: FAISAL
A10: TC.TR.MRes.007 | G10: Verify Table listing result | H10: L | K10: Data displayed list should be filtered according to selected criteria | L10: PASS | N10: N/A | R10: FAISAL
A11: TC.TR.MRes.008 | G11: Reset button | H11: L | K11: All fields should be cleared | L11: PASS | N11: N/A | R11: FAISAL
A12: TC.TR.MRes.009 | G12: Search Button | H12: L | K12: All fields should be cleared | L12: PASS | N12: N/A | R12: FAISAL
A13: TC.TR.MRes.010 | G13: Update Complaint | H13: H | K13: Successfully update application | N13: N/A | R13: FAISAL
A14: TC.TR.MRes.011 | G14: Submission | H14: H | K14: Success submit application and display success message | N14: N/A | R14: FAISAL
A15: TC.TR.MRes.012 | E15: Inspect Complaint | G15: Verify Table listing result | H15: M | K15: Data displayed list should be filtered according to selected criteria | N15: N/A | R15: FAISAL
A16: TC.TR.MRes.013 | G16: Search complaint list | H16: L | K16: Successfully search as per criteria selected | L16: FAIL | N16: N/A | O16: FAIL | P16: 38485 | Q16: Complaint date not display once select specific date | R16: FAISAL
A17: TC.TR.MRes.014 | G17: Update Complaint | H17: H | K17: Successfully update application | N17: N/A | R17: FAISAL
A18: TC.TR.MRes.015 | G18: Download | H18: M | K18: Successfully download Borang F | N18: N/A | R18: FAISAL
A19: TC.TR.MRes.016 | G19: Submission | H19: H | K19: Success submit application and display success message | N19: N/A | R19: FAISAL
A20: TC.TR.MRes.017 | E20: Endorse Complaint | G20: Verify Table listing result | H20: M | K20: Data displayed list should be filtered according to selected criteria | N20: N/A | R20: FAISAL
A21: TC.TR.MRes.018 | G21: Search complaint list | H21: L | K21: Successfully search as per criteria selected | N21: N/A | R21: FAISAL
A22: TC.TR.MRes.019 | G22: Update Application | H22: H | K22: Successfully update application | N22: N/A | R22: FAISAL
A23: TC.TR.MRes.020 | G23: Download | H23: M | K23: Successfully download Borang F | N23: N/A | R23: FAISAL
A24: TC.TR.MRes.021 | G24: Submission | H24: H | K24: Success submit application and display success message | L24: FAIL | N24: N/A | O24: FAIL | P24: 38484 | Q24: view status action taken | R24: FAISAL
A25: TC.TR.MRes.022 | E25: Monthly Reporting Reporting | G25: Single Search Criteria | H25: L | K25: Successfully search as per criteria selected | L25: PASS | M25: PASS | N25: N/A | O25: PASS | R25: FAISAL
A26: TC.TR.MRes.023 | G26: Search Criteria | H26: L | K26: Successfully search as per criteria selected | L26: PASS | M26: PASS | N26: N/A | O26: PASS | R26: FAISAL
A27: TC.TR.MRes.024 | G27: Reset button | H27: L | K27: All fields should be cleared | L27: PASS | M27: PASS | N27: N/A | O27: PASS | R27: FAISAL
A28: TC.TR.MRes.025 | G28: Search Button | H28: L | K28: All fields should be cleared | L28: PASS | M28: PASS | N28: N/A | O28: PASS | R28: FAISAL
A29: TC.TR.MRes.026 | G29: Print button | H29: M | K29: Successfully generate PDF file | L29: FAIL | M29: FAIL | N29: N/A | O29: FAIL | P29: 38483 | R29: FAISAL
A30: TC.TR.MRes.027 | G30: Export button | H30: M | K30: Successfully generate excel | L30: FAIL | M30: FAIL | N30: N/A | O30: FAIL | P30: 38483 | R30: FAISAL
A31: TC.TR.MRes.028 | E31: Complaint Summary by Stages | G31: Print button | H31: M | K31: Successfully generate PDF file | L31: PASS | M31: PASS | N31: N/A | O31: PASS | R31: FAISAL
A32: TC.TR.MRes.029 | G32: Export button | H32: M | K32: Successfully generate excel | L32: FAIL | M32: FAIL | N32: N/A | O32: FAIL | Q32: Missing title | R32: FAISAL
A33: TC.TR.MRes.030 | D33: Global Search | E33: Complaint List | G33: Verify Table listing result | H33: M | K33: Data displayed list should be filtered according to selected criteria | N33: N/A | R33: FAISAL
A34: TC.TR.MRes.031 | G34: Search Criteria | H34: L | K34: Successfully search as per criteria selected | L34: PASS | M34: PASS | N34: N/A | O34: PASS | R34: FAISAL
A35: TC.TR.MRes.032 | G35: Verify Complaint details | H35: M | K35: Data display as expected | N35: N/A | R35: FAISAL
A36: TC.TR.MRes.033 | E36: FWe List | G36: Verify Table listing result | H36: M | K36: Data displayed list should be filtered according to selected criteria | N36: N/A
A37: TC.TR.MRes.034 | G37: Search Criteria | H37: L | K37: Successfully search as per criteria selected | N37: N/A
A38: TC.TR.MRes.035 | G38: Verify Complaint details | H38: M | K38: Data display as expected | N38: N/A
A39: TC.TR.MRes.036 | E39: eQuota List | G39: Verify Table listing result | H39: M | K39: Data displayed list should be filtered according to selected criteria | N39: N/A
A40: TC.TR.MRes.037 | G40: Search Criteria | H40: L | K40: Successfully search as per criteria selected | N40: N/A
...
