Workbook

Sheet Doc Info
B1: Review
B3: Review Log
G4: Ref. No.: BSB-QA-FWCMS-153-CRD-V1.0
B5: Project Name | D5: FWCMS Tech Refresh - 34384
B7: Document Information
B8: Sl # | C8: Date | D8: Updated By | E8: Update Summary | F8: Reviewed By | G8: Reviewed Date
B9: 1 | C9: 46076 | D9: Raihan | E9: Draft TC
B10: 2 | C10: 46118 | D10: Faisal | E10: Update TC
B11: 3
B12: 4
B13: 5

Sheet Progress
A1: Module | B1: Total | C1: Passed | D1: Failed | E1: Blocked | F1: In Progress | G1: Not Executed | H1: Pass Completion (%) | I1: Total Test Completion (%)
A2: eComplaint Reporting | B2: =SUM(C2:G2) -> 125 | C2: ='eCom Reporting'!N1 + eComplaint!N1 -> 125 | D2: ='eCom Reporting'!O1 + eComplaint!O1 -> 0 | E2: ='eCom Reporting'!R1 + eComplaint!R1 -> 0 | F2: ='eCom Reporting'!Q1 + eComplaint!Q1 -> 0 | G2: ='eCom Reporting'!P1 + eComplaint!P1 -> 0 | H2: =C2/B2 -> 1 | I2: =(C2+D2)/B2 -> 1 | J2: Faisal | K2: +syamil & raimi
A3: NNS Quota Allocation Reporting | B3: =SUM(C3:G3) -> 44 | C3: ='NNS Quota Allocation Reporting'!N1 -> 40 | D3: ='NNS Quota Allocation Reporting'!O1 -> 0 | E3: ='NNS Quota Allocation Reporting'!R1 -> 4 | F3: ='NNS Quota Allocation Reporting'!Q1 -> 0 | G3: ='NNS Quota Allocation Reporting'!P1 -> 0 | H3: =C3/B3 -> 0.90909091 | I3: =(C3+D3+E3)/B3 -> 1 | J3: Qina
A4: Quota Application Reporting | B4: =SUM(C4:G4) -> 100 | C4: ='Quota Application Reporting'!N1 -> 98 | D4: ='Quota Application Reporting'!O1 -> 0 | E4: ='Quota Application Reporting'!R1 -> 2 | F4: ='Quota Application Reporting'!Q1 -> 0 | G4: ='Quota Application Reporting'!P1 -> 0 | H4: =C4/B4 -> 0.98 | I4: =(C4+D4+E4)/B4 -> 1 | J4: Faisal
A5: IDM UAT Feedback | B5: =SUM(C5:G5) -> 81 | C5: ='IDM UAT Feedback'!N1+'#37022'!N1 -> 81 | D5: ='IDM UAT Feedback'!O1+'#37022'!O1 -> 0 | E5: ='IDM UAT Feedback'!R1+'#37022'!R1 -> 0 | F5: ='IDM UAT Feedback'!Q1+'#37022'!Q1 -> 0 | G5: ='IDM UAT Feedback'!P1+'#37022'!P1 -> 0 | H5: =C5/B5 -> 1 | I5: =(C5+D5+E5)/B5 -> 1 | J5: Yhuvan
A6: IDM - KDNK | B6: =SUM(C6:G6) -> 100 | C6: ='IDM - KDNK'!N1 -> 100 | D6: ='IDM - KDNK'!O1 -> 0 | E6: ='IDM - KDNK'!R1 -> 0 | F6: ='IDM - KDNK'!Q1 -> 0 | G6: ='IDM - KDNK'!P1 -> 0 | H6: =C6/B6 -> 1 | I6: =(C6+D6)/B6 -> 1 | J6: Yhuvan
A7: IDM - KESUMA / PERKESO | B7: =SUM(C7:G7) -> 59 | C7: ='IDM - KESUMA'!N1 -> 59 | D7: ='IDM - KESUMA'!O1 -> 0 | E7: ='IDM - KESUMA'!R1 -> 0 | F7: ='IDM - KESUMA'!Q1 -> 0 | G7: ='IDM - KESUMA'!P1 -> 0 | H7: =C7/B7 -> 1 | I7: =(C7+D7)/B7 -> 1 | J7: Yhuvan
A8: Biodata Screening | B8: =SUM(C8:G8) -> 67 | C8: ='Biodata Screening'!N1 -> 37 | D8: ='Biodata Screening'!O1 -> 19 | E8: ='Biodata Screening'!R1 -> 0 | F8: ='Biodata Screening'!Q1 -> 1 | G8: ='Biodata Screening'!P1 -> 10 | H8: =C8/B8 -> 0.55223881 | I8: =(C8+D8)/B8 -> 0.8358209 | J8: Syasya
A9: TOTAL | B9: =SUM(B2:B8) -> 576 | C9: =SUM(C2:C8) -> 540 | D9: =SUM(D2:D8) -> 19 | E9: =SUM(E2:E8) -> 6 | F9: =SUM(F2:F8) -> 1 | G9: =SUM(G2:G8) -> 10 | H9: =C9/B9 -> 0.9375 | I9: =(C9+D9)/B9 -> 0.97048611

Sheet eCom Reporting
A1: Case ID | B1: Redmine User Story | C1: Tracker | D1: Scenario | E1: Pre Condition | F1: Case | G1: Steps | H1: Test Data | I1: Expected Result | J1: Result | K1: Redmine Defect | L1: Additional/Comments/Issues | M1: QA PIC | N1: =SUM(N2:N94) -> 20 | O1: =SUM(O2:O94) -> 0 | P1: =SUM(P2:P94) -> 0 | Q1: =SUM(Q2:Q94) -> 0 | R1: =SUM(R2:R94) -> 0
A2: eComplaint- Monthly Complaint Report | N2: =COUNTIF($J3:J13,"PASS") -> 11 | O2: =COUNTIF($J3:J13,"FAIL") -> 0 | P2: =COUNTBLANK(J3:J13) -> 0 | Q2: =COUNTIF($J3:J13,"IN PROGRESS") -> 0 | R2: =COUNTIF($J3:J13,"BLOCKED") -> 0
A3: TC.TR.RPTeCom.001 | B3: #28118 #35137 | C3: User Story | D3: Test Search Form | E3: User Role: MENTERI_JTKSM_ADMIN KSM_JTK_HQ_ADMIN KSM_STATE_ADMIN KSM_STATE_USER JTKSM_OC_ALL JTKSRWK_OC_ALL JTKSBH_OC_ALL KSM_JTKSRWK_ADMIN KSM_JTKSBH_ADMIN | F3: Verify all labels | I3: Following must be correct : a. Spelling b. Font (Standard) c. Color (Standard) d. Translation (Locale) | J3: PASS | K3: 37613 | L3: MENTERI_JTKSM_ADMIN - sahi.kesuma2908@yopmail.com - ok KSM_JTK_HQ_ADMIN - sahi.automation9279@yopmail.com - ok KSM_STATE_ADMIN - sahitest.auto2820@yopmail.com - ok KSM_STATE_USER - sahitest.auto2760@yopmail.com - ok JTKSM_OC_ALL - sahijtksm.auto3642@yopmail.com- ok JTKSRWK_OC_ALL - sahitest.auto7408@yopmail.com- ok JTKSBH_OC_ALL - sahitest.auto3733@yopmail.com - ok KSM_JTKSRWK_ADMIN - sahitest.auto6118@yopmail.com - ok KSM_JTKSBH_ADMIN - sahitest.auto5265@yopmail.com - ok | M3: FAISAL
A4: TC.TR.RPTeCom.002 | F4: Verify alignments | I4: All labels / fields are properly aligned | J4: PASS | K4: 37614 | M4: FAISAL
A5: TC.TR.RPTeCom.003 | F5: Verify breadcrumbs | I5: Breadcrumbs as per page title with correct hierarchy | J5: PASS | M5: FAISAL
A6: TC.TR.RPTeCom.004 | F6: Check Single Search Criteria | G6: Search each of search criteria | I6: Successfully search as per criteria selected | J6: PASS | M6: FAISAL
A7: TC.TR.RPTeCom.005 | F7: Check Combination of Search Criteria | G7: Search combination of search criteria | I7: Successfully search as per criteria selected | J7: PASS | M7: FAISAL
A8: TC.TR.RPTeCom.006 | D8: Verify Search Result | F8: Verify column headers | I8: All required columns should be available with appropriate labels. *All search criteria value should have a column in result table. Start/ End date should be represented by 1 date column only. | J8: PASS | K8: 37614 | M8: FAISAL
A9: TC.TR.RPTeCom.007 | F9: Verify search result data | I9: Data displayed list should be filtered according to selected criteria | J9: PASS | M9: FAISAL
A10: TC.TR.RPTeCom.008 | F10: Verify total record count | I10: Total record count should be displayed | J10: PASS | M10: FAISAL
A11: TC.TR.RPTeCom.009 | F11: Pagination | I11: Pagination should be enabled if there are too many rows (15 rows per page) | J11: PASS | M11: FAISAL
A12: TC.TR.RPTeCom.010 | F12: Navigate pagination | I12: Next, Previous, First and Last page pagination functionality should be working | J12: PASS | M12: FAISAL
A13: TC.TR.RPTeCom.011 | F13: Reset button | G13: Enter search parameter and reset. | I13: All fields should be cleared | J13: PASS | M13: FAISAL
A14: eComplaint- Complaint Summary by Stage | N14: =COUNTIF($J15:J23,"PASS") -> 9 | O14: =COUNTIF($J15:J23,"FAIL") -> 0 | P14: =COUNTBLANK(J15:J23) -> 0 | Q14: =COUNTIF($J15:J23,"IN PROGRESS") -> 0 | R14: =COUNTIF($J15:J23,"BLOCKED") -> 0
A15: TC.TR.RPTeCom.012 | B15: #28119 #35138 | C15: User Story | D15: Test Search Form | E15: User Role: KSM_JTK_HQ_ADMIN KSM_STATE_ADMIN JTKSM_OC_ALL JTKSRWK_OC_ALL JTKSBH_OC_ALL KSM_JTKSRWK_ADMIN KSM_JTKSBH_ADMIN | F15: Verify all labels | I15: Following must be correct : a. Spelling b. Font (Standard) c. Color (Standard) d. Translation (Locale) | J15: PASS | K15: 37612 37708 | M15: FAISAL
A16: TC.TR.RPTeCom.013 | F16: Verify alignments | I16: All labels / fields are properly aligned | J16: PASS | M16: FAISAL
A17: TC.TR.RPTeCom.014 | F17: Verify breadcrumbs | I17: Breadcrumbs as per page title with correct hierarchy | J17: PASS | M17: FAISAL
A18: TC.TR.RPTeCom.015 | F18: Check Single Search Criteria | G18: Search each of search criteria | I18: Successfully search as per criteria selected | J18: PASS | K18: 37744 | M18: FAISAL
A19: TC.TR.RPTeCom.016 | F19: Check Combination of Search Criteria | G19: Search combination of search criteria | I19: Successfully search as per criteria selected | J19: PASS | K19: 37744 | M19: FAISAL
A20: TC.TR.RPTeCom.017 | D20: Verify Search Result | F20: Verify column headers | I20: All required columns should be available with appropriate labels. *All search criteria value should have a column in result table. Start/ End date should be represented by 1 date column only. | J20: PASS | M20: FAISAL
A21: TC.TR.RPTeCom.018 | F21: Verify total record count | I21: Total record count should be displayed | J21: PASS | K21: 37744 | M21: FAISAL
A22: TC.TR.RPTeCom.019 | F22: Pagination | I22: Pagination should be enabled if there are too many rows (15 rows per page) | J22: PASS | M22: FAISAL
A23: TC.TR.RPTeCom.020 | F23: Navigate pagination | I23: Next, Previous, First and Last page pagination functionality should be working | J23: PASS | K23: 37709 | M23: FAISAL

Sheet eComplaint
A1: Case ID | B1: Redmine User Story | C1: Tracker | D1: Scenario | E1: Pre Condition | F1: Case | G1: Steps | H1: Test Data | I1: Expected Result | J1: Result | K1: Redmine Defect | L1: Additional/Comments/Issues | M1: QA PIC | N1: =SUM(N2:N136) -> 105 | O1: =SUM(O2:O136) -> 0 | P1: =SUM(P2:P136) -> 0 | Q1: =SUM(Q2:Q136) -> 0 | R1: =SUM(R2:R136) -> 0
A2: Verify Complaint | N2: =COUNTIF($J3:J25,"PASS") -> 23 | O2: =COUNTIF($J3:J25,"FAIL") -> 0 | P2: =COUNTBLANK(J3:J25) -> 0 | Q2: =COUNTIF($J3:J25,"IN PROGRESS") -> 0 | R2: =COUNTIF($J3:J25,"BLOCKED") -> 0
A3: TC.TR.eCom.001 | B3: #28105 | C3: User Story | D3: Test Search Form | E3: User Role: JTKSM_OC_ALL | F3: Verify all labels | I3: Following must be correct : a. Spelling b. Font (Standard) c. Color (Standard) d. Translation (Locale) | J3: PASS | K3: 37823 37826 | M3: FAISAL
A4: TC.TR.eCom.002 | F4: Verify alignments | I4: All labels / fields are properly aligned | J4: PASS | M4: FAISAL
A5: TC.TR.eCom.003 | F5: Verify breadcrumbs | I5: Breadcrumbs as per page title with correct hierarchy | J5: PASS | K5: 37746 | M5: FAISAL
A6: TC.TR.eCom.004 | F6: Check Single Search Criteria | G6: Search each of search criteria | I6: Successfully search as per criteria selected | J6: PASS | M6: FAISAL
A7: TC.TR.eCom.005 | F7: Check Combination of Search Criteria | G7: Search combination of search criteria | I7: Successfully search as per criteria selected | J7: PASS | M7: FAISAL
A8: TC.TR.eCom.006 | F8: End date less than start date | I8: Unable to search and display proper error message | J8: PASS | K8: 37745 | M8: FAISAL
A9: TC.TR.eCom.007 | F9: End date more than start date | I9: Able to search | J9: PASS | M9: FAISAL
A10: TC.TR.eCom.008 | F10: End date equal start date | I10: Able to search | J10: PASS | M10: FAISAL
A11: TC.TR.eCom.009 | D11: Verify Search Result | F11: Verify column headers | I11: All required columns should be available with appropriate labels. *All search criteria value should have a column in result table. Start/ End date should be represented by 1 date column only. | J11: PASS | K11: missing breadcrump | M11: FAISAL
A12: TC.TR.eCom.010 | F12: Verify search result data | I12: Data displayed list should be filtered according to selected criteria | J12: PASS | M12: FAISAL
A13: TC.TR.eCom.011 | F13: Verify total record count | I13: Total record count should be displayed | J13: PASS | M13: FAISAL
A14: TC.TR.eCom.012 | F14: Pagination | I14: Pagination should be enabled if there are too many rows (15 rows per page) | J14: PASS | M14: FAISAL
A15: TC.TR.eCom.013 | F15: Navigate pagination | I15: Next, Previous, First and Last page pagination functionality should be working | J15: PASS | M15: FAISAL
A16: TC.TR.eCom.014 | F16: Reset button | G16: Enter search parameter and reset. | I16: All fields should be cleared | J16: PASS | K16: 37748 | M16: FAISAL
A17: TC.TR.eCom.015 | B17: #28106 | C17: User Story | D17: Application Details | F17: Verify all labels | I17: Following must be correct : a. Spelling b. Font (Standard) c. Color (Standard) d. Translation (Locale) | J17: PASS | K17: 37823 | M17: FAISAL
A18: TC.TR.eCom.016 | F18: Verify pre-populated data | I18: Available data should auto populate by default based on data in DB | J18: PASS | K18: 37787 | M18: FAISAL
A19: TC.TR.eCom.017 | F19: Result : Verify | I19: 1. Remarks is mandatory to fill 2. Employer received email verified. | J19: PASS | M19: FAISAL
A20: TC.TR.eCom.018 | F20: Result : Verification Unsuccessful | I20: 1. Application status : 2. Employer will received an email | J20: PASS | L20: WFWJ0877244613 | M20: FAISAL
A21: TC.TR.eCom.019 | F21: Submit without entering any mandatory fields | I21: Display proper mandatory field error message | J21: PASS | M21: FAISAL
A22: TC.TR.eCom.020 | F22: Verify Assign to Inspector listing | I22: List out all assign inspector | J22: PASS | M22: FAISAL
A23: TC.TR.eCom.021 | F23: Verify popup message | I23: Success message as per requirement / standard. Check case & spelling. | J23: PASS | K23: 37824 | L23: No message for uccess/unsuccessful | M23: FAISAL
A24: TC.TR.eCom.022 | B24: #35189 | C24: User Story | D24: View Application | F24: Verify all labels | I24: Following must be correct : a. Spelling b. Font (Standard) c. Color (Standard) d. Translation (Locale) | J24: PASS | K24: 37823 | M24: FAISAL
A25: TC.TR.eCom.023 | F25: Verify pre-populated data | I25: Available data should auto populate by default based on data in DB | J25: PASS | M25: FAISAL
A26: Inspect Complaint | N26: =COUNTIF($J27:J46,"PASS") -> 20 | O26: =COUNTIF($J27:J46,"FAIL") -> 0 | P26: =COUNTBLANK(J27:J46) -> 0 | Q26: =COUNTIF($J27:J46,"IN PROGRESS") -> 0 | R26: =COUNTIF($J27:J46,"BLOCKED") -> 0
A27: TC.TR.eCom.024 | B27: #28108 | C27: User Story | D27: Test Search Form | E27: User Role: JTKSM_OC_ALL - Ketua Pejabat JTKSM_INSPECTOR - Pegawai Penyiasat FWe & WFW JTKSM_INSPECTOR WFW - Pegawai Penyiasat WFW | F27: Verify all labels | I27: Following must be correct : a. Spelling b. Font (Standard) c. Color (Standard) d. Translation (Locale) | J27: PASS | K27: 37825 | M27: FAISAL
A28: TC.TR.eCom.025 | F28: Verify alignments | I28: All labels / fields are properly aligned | J28: PASS | K28: 37825 | M28: FAISAL
A29: TC.TR.eCom.026 | F29: Verify breadcrumbs | I29: Breadcrumbs as per page title with correct hierarchy | J29: PASS | M29: FAISAL
A30: TC.TR.eCom.027 | F30: Check Single Search Criteria | G30: Search each of search criteria | I30: Successfully search as per criteria selected | J30: PASS | M30: FAISAL
A31: TC.TR.eCom.028 | F31: Check Combination of Search Criteria | G31: Search combination of search criteria | I31: Successfully search as per criteria selected | J31: PASS | M31: FAISAL
A32: TC.TR.eCom.029 | F32: End date less than start date | I32: Unable to search and display proper error message | J32: PASS | K32: 37745 | M32: FAISAL
A33: TC.TR.eCom.030 | F33: End date more than start date | I33: Able to search | J33: PASS | M33: FAISAL
A34: TC.TR.eCom.031 | F34: End date equal start date | I34: Able to search | J34: PASS | M34: FAISAL
A35: TC.TR.eCom.032 | D35: Verify Search Result | F35: Verify column headers | I35: All required columns should be available with appropriate labels. *All search criteria value should have a column in result table. Start/ End date should be represented by 1 date column only. | J35: PASS | M35: FAISAL
A36: TC.TR.eCom.033 | F36: Verify search result data | I36: Data displayed list should be filtered according to selected criteria | J36: PASS | M36: FAISAL
A37: TC.TR.eCom.034 | F37: Verify total record count | I37: Total record count should be displayed | J37: PASS | M37: FAISAL
A38: TC.TR.eCom.035 | F38: Pagination | I38: Pagination should be enabled if there are too many rows (15 rows per page) | J38: PASS | M38: FAISAL
A39: TC.TR.eCom.036 | F39: Navigate pagination | I39: Next, Previous, First and Last page pagination functionality should be working | J39: PASS | M39: FAISAL
A40: TC.TR.eCom.037 | F40: Reset button | G40: Enter search parameter and reset. | I40: All fields should be cleared | J40: PASS | M40: FAISAL
...

Sheet NNS Quota Allocation Reporting
A1: Case ID | B1: Redmine User Story | C1: Tracker | D1: Scenario | E1: Pre Condition | F1: Case | G1: Steps | H1: Test Data | I1: Expected Result | J1: Result | K1: Redmine Defect | L1: Additional/Comments/Issues | M1: QA PIC | N1: =SUM(N2:N101) -> 40 | O1: =SUM(O2:O101) -> 0 | P1: =SUM(P2:P101) -> 0 | Q1: =SUM(Q2:Q101) -> 0 | R1: =SUM(R2:R101) -> 4
A2: NNS Quota Allocation Report - By Sector | N2: =COUNTIF($J3:J16,"PASS") -> 12 | O2: =COUNTIF($J3:J16,"FAIL") -> 0 | P2: =COUNTBLANK(J3:J16) -> 0 | Q2: =COUNTIF($J3:J16,"IN PROGRESS") -> 0 | R2: =COUNTIF($J3:J16,"BLOCKED") -> 2
A3: TC.TR.RPTNNS.001 | B3: #35127 | C3: User Story | D3: Test Search Form | E3: User Role: -SUPER_ADMIN | F3: Verify all labels | I3: Following must be correct : a. Spelling b. Font (Standard) c. Color (Standard) d. Translation (Locale) | J3: PASS | K3: #38104 #38113 | M3: QINA
A4: TC.TR.RPTNNS.002 | F4: Verify alignments | I4: All labels / fields are properly aligned | J4: PASS | K4: #38110 #38111 #38149 | M4: QINA
A5: TC.TR.RPTNNS.003 | F5: Verify breadcrumbs | I5: Breadcrumbs as per page title with correct hierarchy | J5: PASS | K5: #38104 #38113 | M5: QINA
A6: TC.TR.RPTNNS.004 | F6: Check Single Search Criteria | G6: Search each of search criteria | I6: Successfully search as per criteria selected | J6: PASS | K6: #38110 #38111 #38149 | M6: QINA
A7: TC.TR.RPTNNS.005 | F7: Check Combination of Search Criteria | G7: Search combination of search criteria | I7: Successfully search as per criteria selected | J7: PASS | K7: #38114 #38119 | M7: QINA
A8: TC.TR.RPTNNS.006 | F8: End date less than start date | I8: Unable to search and display proper error message | J8: PASS | K8: #38110 #38111 #38114 #38149 | M8: QINA
A9: TC.TR.RPTNNS.007 | F9: End date more than start date | I9: Able to search | J9: PASS | M9: QINA
A10: TC.TR.RPTNNS.008 | F10: End date equal start date | I10: Able to search | J10: PASS | M10: QINA
A11: TC.TR.RPTNNS.009 | D11: Verify Search Result | F11: Verify column headers | I11: All required columns should be available with appropriate labels. | J11: PASS | M11: QINA
A12: TC.TR.RPTNNS.010 | F12: Verify search result data | I12: Data displayed list should be filtered according to selected criteria | J12: PASS | K12: #38114 #38119 | M12: QINA
A13: TC.TR.RPTNNS.011 | F13: Verify total record count | I13: Total record count should be displayed | J13: PASS | M13: QINA
A14: TC.TR.RPTNNS.012 | F14: Reset button | G14: Enter search parameter and reset. | I14: All fields should be cleared | J14: PASS | M14: QINA
A15: TC.TR.RPTNNS.013 | F15: Print Button | I15: Successfully generate pdf document | J15: BLOCKED | K15: #38124 | M15: QINA
A16: TC.TR.RPTNNS.014 | F16: Export Button | I16: Successfully generate excel document | J16: BLOCKED | K16: #38124 | M16: QINA
A17: NNS Quota Allocation Report - Top 10 Employers | N17: =COUNTIF($J18:J31,"PASS") -> 14 | O17: =COUNTIF($J18:J31,"FAIL") -> 0 | P17: =COUNTBLANK(J18:J31) -> 0 | Q17: =COUNTIF($J18:J31,"IN PROGRESS") -> 0 | R17: =COUNTIF($J18:J31,"BLOCKED") -> 0
A18: TC.TR.RPTNNS.015 | B18: #35128 | C18: User Story | D18: Test Search Form | E18: User Role: -SUPER_ADMIN | F18: Verify all labels | I18: Following must be correct : a. Spelling b. Font (Standard) c. Color (Standard) d. Translation (Locale) | J18: PASS | K18: #38104 #38113 | M18: QINA
A19: TC.TR.RPTNNS.016 | F19: Verify alignments | I19: All labels / fields are properly aligned | J19: PASS | K19: #38145 #38127 #38150 | M19: QINA
A20: TC.TR.RPTNNS.017 | F20: Verify breadcrumbs | I20: Breadcrumbs as per page title with correct hierarchy | J20: PASS | K20: #38104 #38113 | M20: QINA
A21: TC.TR.RPTNNS.018 | F21: Check Single Search Criteria | G21: Search each of search criteria | I21: Successfully search as per criteria selected | J21: PASS | K21: #38134 | M21: QINA
A22: TC.TR.RPTNNS.019 | F22: Check Combination of Search Criteria | G22: Search combination of search criteria | I22: Successfully search as per criteria selected | J22: PASS | K22: #38134 | M22: QINA
A23: TC.TR.RPTNNS.020 | F23: End date less than start date | I23: Unable to search and display proper error message | J23: PASS | K23: #38127 #38150 | M23: QINA
A24: TC.TR.RPTNNS.021 | F24: End date more than start date | I24: Able to search | J24: PASS | M24: QINA
A25: TC.TR.RPTNNS.022 | F25: End date equal start date | I25: Able to search | J25: PASS | M25: QINA
A26: TC.TR.RPTNNS.023 | D26: Verify Search Result | F26: Verify column headers | I26: All required columns should be available with appropriate labels. | J26: PASS | M26: QINA
A27: TC.TR.RPTNNS.024 | F27: Verify search result data | I27: Data displayed list should be filtered according to selected criteria | J27: PASS | K27: #38134 | M27: QINA
A28: TC.TR.RPTNNS.025 | F28: Verify total record count | I28: Total record count should be displayed | J28: PASS | K28: #38134 #38153 | M28: QINA
A29: TC.TR.RPTNNS.026 | F29: Print Button | I29: Successfully generate pdf document | J29: PASS | K29: #38139 | M29: QINA
A30: TC.TR.RPTNNS.027 | F30: Export Button | I30: Successfully generate excel document | J30: PASS | K30: #38139 | M30: QINA
A31: TC.TR.RPTNNS.028 | F31: Reset button | G31: Enter search parameter and reset. | I31: All fields should be cleared | J31: PASS | K31: #38127 | M31: QINA
A32: NNS Quota Allocation Report - Transaction Report | N32: =COUNTIF($J33:J48,"PASS") -> 14 | O32: =COUNTIF($J33:J48,"FAIL") -> 0 | P32: =COUNTBLANK(J33:J48) -> 0 | Q32: =COUNTIF($J33:J48,"IN PROGRESS") -> 0 | R32: =COUNTIF($J33:J48,"BLOCKED") -> 2
A33: TC.TR.RPTNNS.029 | B33: #35129 | C33: User Story | D33: Test Search Form | E33: User Role: -SUPER_ADMIN | F33: Verify all labels | I33: Following must be correct : a. Spelling b. Font (Standard) c. Color (Standard) d. Translation (Locale) | J33: PASS | K33: #38104 #38113 | M33: QINA
A34: TC.TR.RPTNNS.030 | F34: Verify alignments | I34: All labels / fields are properly aligned | J34: PASS | K34: #38146 #38151 | M34: QINA
A35: TC.TR.RPTNNS.031 | F35: Verify breadcrumbs | I35: Breadcrumbs as per page title with correct hierarchy | J35: PASS | K35: #38104 #38113 | M35: QINA
A36: TC.TR.RPTNNS.032 | F36: Check Single Search Criteria | G36: Search each of search criteria | I36: Successfully search as per criteria selected | J36: PASS | M36: QINA
A37: TC.TR.RPTNNS.033 | F37: Check Combination of Search Criteria | G37: Search combination of search criteria | I37: Successfully search as per criteria selected | J37: PASS | K37: #38152 | M37: QINA
A38: TC.TR.RPTNNS.034 | F38: End date less than start date | I38: Unable to search and display proper error message | J38: PASS | K38: #38147 | M38: QINA
A39: TC.TR.RPTNNS.035 | F39: End date more than start date | I39: Able to search | J39: PASS | M39: QINA
A40: TC.TR.RPTNNS.036 | F40: End date equal start date | I40: Able to search | J40: PASS | M40: QINA
...

Sheet Quota Application Reporting
A1: Case ID | B1: Redmine User Story | C1: Tracker | D1: Scenario | E1: Pre Condition | F1: Case | G1: Steps | H1: Test Data | I1: Expected Result | J1: Result | K1: Redmine Defect | L1: Additional/Comments/Issues | M1: QA PIC | N1: =SUM(N2:N115) -> 98 | O1: =SUM(O2:O115) -> 0 | P1: =SUM(P2:P115) -> 0 | Q1: =SUM(Q2:Q115) -> 0 | R1: =SUM(R2:R115) -> 2
A2: Quota Application Report - Summary Page | N2: =COUNTIF($J3:J20,"PASS") -> 18 | O2: =COUNTIF($J3:J20,"FAIL") -> 0 | P2: =COUNTBLANK(J3:J20) -> 0 | Q2: =COUNTIF($J3:J20,"IN PROGRESS") -> 0 | R2: =COUNTIF($J3:J20,"BLOCKED") -> 0
A3: TC.TR.RPTeQuora.001 | B3: #34384 #35117 #35130 #35131 #37382 #37471 | C3: User Story | D3: Test Search Form | E3: User Role: -SUPER_ADMIN | F3: Verify all labels | H3: sahitest.auto2824@yopmail.com | I3: Following must be correct : a. Spelling b. Font (Standard) c. Color (Standard) d. Translation (Locale) | J3: PASS | K3: #38126 | M3: FAISAL
A4: TC.TR.RPTeQuora.002 | F4: Verify alignments | I4: All labels / fields are properly aligned | J4: PASS | M4: FAISAL
A5: TC.TR.RPTeQuora.003 | F5: Verify breadcrumbs | I5: Breadcrumbs as per page title with correct hierarchy | J5: PASS | K5: #38120 | M5: SYASYA
A6: TC.TR.RPTeQuora.004 | F6: Check Single Search Criteria | G6: Search each of search criteria | I6: Successfully search as per criteria selected | J6: PASS | K6: #38121 | M6: SYASYA
A7: TC.TR.RPTeQuora.005 | F7: Check Combination of Search Criteria | G7: Search combination of search criteria | I7: Successfully search as per criteria selected | J7: PASS | K7: #38121 | M7: SYASYA
A8: TC.TR.RPTeQuora.006 | F8: End date less than start date | I8: Unable to search and display proper error message | J8: PASS | K8: #38123 | M8: SYASYA
A9: TC.TR.RPTeQuora.007 | F9: End date more than start date | I9: Able to search | J9: PASS | M9: FAISAL
A10: TC.TR.RPTeQuora.008 | F10: End date equal start date | I10: Able to search | J10: PASS | M10: FAISAL
A11: TC.TR.RPTeQuora.009 | D11: Verify Search Result | F11: Verify column headers | I11: All required columns should be available with appropriate labels. | J11: PASS | K11: #38126 | M11: SYASYA
A12: TC.TR.RPTeQuora.010 | F12: Verify search result data | I12: Data displayed list should be filtered according to selected criteria | J12: PASS | K12: #38128 | M12: FAISAL
A13: TC.TR.RPTeQuora.011 | F13: Verify total record count | I13: Total record count should be displayed | J13: PASS | M13: FAISAL
A14: TC.TR.RPTeQuora.012 | F14: Pagination | I14: Pagination should be enabled if there are too many rows (15 rows per page) | J14: PASS | M14: SYASYA
A15: TC.TR.RPTeQuora.013 | F15: Navigate pagination | I15: Next, Previous, First and Last page pagination functionality should be working | J15: PASS | M15: FAISAL
A16: TC.TR.RPTeQuora.014 | F16: Reset button | G16: Enter search parameter and reset. | I16: All fields should be cleared | J16: PASS | M16: FAISAL
A17: TC.TR.RPTeQuora.015 | D17: Approver Slip | F17: View Approver slip | I17: Successfully view approver slip | J17: PASS | K17: #38144 | M17: FAISAL
A18: TC.TR.RPTeQuora.016 | D18: Verify Application | F18: Verify application | I18: Successfully verify application | J18: PASS | M18: FAISAL
A19: TC.TR.RPTeQuora.017 | D19: Print Button | F19: Print Button | I19: Successfully generate pdf document | J19: PASS | M19: FAISAL
A20: TC.TR.RPTeQuora.018 | D20: Export Button | F20: Export Button | I20: Successfully generate excel document | J20: PASS | M20: FAISAL
A21: Quota Application Report - Quota Application (Biasa) | N21: =COUNTIF($J22:J39,"PASS") -> 18 | O21: =COUNTIF($J22:J39,"FAIL") -> 0 | P21: =COUNTBLANK(J22:J39) -> 0 | Q21: =COUNTIF($J22:J39,"IN PROGRESS") -> 0 | R21: =COUNTIF($J22:J39,"BLOCKED") -> 0
A22: TC.TR.RPTeQuora.019 | B22: #35131 | C22: User Story | D22: Test Search Form | E22: User Role: -SUPER_ADMIN | F22: Verify all labels | I22: Following must be correct : a. Spelling b. Font (Standard) c. Color (Standard) d. Translation (Locale) | J22: PASS | M22: FAISAL
A23: TC.TR.RPTeQuora.020 | F23: Verify alignments | I23: All labels / fields are properly aligned | J23: PASS | M23: FAISAL
A24: TC.TR.RPTeQuora.021 | F24: Verify breadcrumbs | I24: Breadcrumbs as per page title with correct hierarchy | J24: PASS | K24: 38208 | M24: FAISAL
A25: TC.TR.RPTeQuora.022 | F25: Check Single Search Criteria | G25: Search each of search criteria | I25: Successfully search as per criteria selected | J25: PASS | M25: FAISAL
A26: TC.TR.RPTeQuora.023 | F26: Check Combination of Search Criteria | G26: Search combination of search criteria | I26: Successfully search as per criteria selected | J26: PASS | K26: 38121 | M26: FAISAL
A27: TC.TR.RPTeQuora.024 | F27: End date less than start date | I27: Unable to search and display proper error message | J27: PASS | K27: 38208 | M27: FAISAL
A28: TC.TR.RPTeQuora.025 | F28: End date more than start date | I28: Able to search | J28: PASS | M28: FAISAL
A29: TC.TR.RPTeQuora.026 | F29: End date equal start date | I29: Able to search | J29: PASS | M29: FAISAL
A30: TC.TR.RPTeQuora.027 | D30: Verify Search Result | F30: Verify column headers | I30: All required columns should be available with appropriate labels. | J30: PASS | M30: FAISAL
A31: TC.TR.RPTeQuora.028 | F31: Verify search result data | I31: Data displayed list should be filtered according to selected criteria | J31: PASS | K31: 38208 | M31: FAISAL
A32: TC.TR.RPTeQuora.029 | F32: Verify total record count | I32: Total record count should be displayed | J32: PASS | M32: FAISAL
A33: TC.TR.RPTeQuora.030 | F33: Pagination | I33: Pagination should be enabled if there are too many rows (15 rows per page) | J33: PASS | K33: 38208 | M33: FAISAL
A34: TC.TR.RPTeQuora.031 | F34: Navigate pagination | I34: Next, Previous, First and Last page pagination functionality should be working | J34: PASS | M34: FAISAL
A35: TC.TR.RPTeQuora.032 | F35: Reset button | G35: Enter search parameter and reset. | I35: All fields should be cleared | J35: PASS | M35: FAISAL
A36: TC.TR.RPTeQuora.033 | D36: Approver Slip | F36: View Approver slip | I36: Successfully view approver slip | J36: PASS | M36: FAISAL
A37: TC.TR.RPTeQuora.034 | D37: Verify Application | F37: Verify application | I37: Successfully verify application | J37: PASS | M37: FAISAL
A38: TC.TR.RPTeQuora.035 | D38: Verify Print and Export Result | F38: Print Button | I38: Successfully generate pdf document | J38: PASS | M38: FAISAL
A39: TC.TR.RPTeQuora.036 | F39: Export Button | I39: Successfully generate excel document | J39: PASS | M39: FAISAL
A40: Top 5 Application by Job Category | N40: =COUNTIF($J41:J53,"PASS") -> 13 | O40: =COUNTIF($J41:J53,"FAIL") -> 0 | P40: =COUNTBLANK(J41:J53) -> 0 | Q40: =COUNTIF($J41:J53,"IN PROGRESS") -> 0 | R40: =COUNTIF($J41:J53,"BLOCKED") -> 0
...

Sheet IDM UAT Feedback
A1: Case ID | B1: Redmine User Story | C1: Tracker | D1: Scenario | E1: Pre Condition | F1: Case | G1: Steps | H1: Test Data | I1: Expected Result | J1: Result | K1: Redmine Defect | L1: Additional/Comments/Issues | M1: QA PIC | N1: =SUM(N2:N104) -> 15 | O1: =SUM(O2:O104) -> 0 | P1: =SUM(P2:P104) -> 0 | Q1: =SUM(Q2:Q104) -> 0 | R1: =SUM(R2:R104) -> 0
A2: TC.TR.JIMFEEDBACK.001 | B2: #36087 | C2: User Story | D2: Pop up Message | F2: Check message in Bahasa Melayu and English for OTP Pop Up message | G2: 1. Click on daftar 2. Fill all the details needed 3. Click Hantar 4. Request OTP 5. Observe | I2: ENG. You can only regenerate the OTP after 15 minutes MY. Anda hanya boleh menjana semula OTP selepas 15 minit | J2: PASS | M2: YHUVAN / LUQMAN | N2: =COUNTIF($J2:J16,"PASS") -> 15 | O2: =COUNTIF($J2:J16,"FAIL") -> 0 | P2: =COUNTBLANK(J2:J16) -> 0 | Q2: =COUNTIF($J2:J16,"IN PROGRESS") -> 0 | R2: =COUNTIF($J2:J16,"BLOCKED") -> 0
A3: TC.TR.JIMFEEDBACK.002 | D3: Pop up Message | F3: Check message in Bahasa Melayu and English for OTP Pop Up message | G3: 1. Click on daftar 2. Fill all the details needed 3. Click Hantar 4. Request OTP 5. Wait another 15 minutes request another OTP 6. Observe | I3: ENG. You can only regenerate the OTP after 15 minutes MY. Anda hanya boleh menjana semula OTP selepas 15 minit | J3: PASS | M3: YHUVAN / LUQMAN
A4: TC.TR.JIMFEEDBACK.003 | B4: #36088 | D4: Jabatan/Agensi Label | F4: Check Jabatan/Agensi Label in Bahasa Melayu and English | G4: 1. Click on daftar 2. Observe the Jabatan/Agensi Label | I4: Eng. Department/ Agency My. Jabatan/ Agensi | J4: PASS | M4: YHUVAN / LUQMAN
A5: TC.TR.JIMFEEDBACK.004 | D5: Jabatan/Agensi Label | E5: Check user that have PRE_REG_IND = NULL SELECT * FROM sppa_env2.IDM_USER_GROUP; | F5: Check Jabatan/Agensi Label in Bahasa Melayu and English | G5: 1. Login with the user that have PRE_REG_IND = NULL 2. Click on Pengurusan Pengguna > Urus Pengguna 3. Click on Cipta Pengguna 4. Observe | I5: Eng. Department/ Agency My. Jabatan/ Agensi | J5: PASS | M5: YHUVAN / LUQMAN
A6: TC.TR.JIMFEEDBACK.005 | B6: #36089 | D6: Sokongan / Kelulusan label | F6: Check on column 'Tindakan' action button | G6: 1. Login 2. Click on Pengurusan Pengguna 3. Click on Sokongan Permohonan ID 4. Click on '…' column tindakan 5. Observe Repeat with Kelulusan Permohonan ID and observe | I6: Eng. a. Claim b. Release My. (become italic) a. Claim b. Release | J6: PASS | M6: YHUVAN / LUQMAN
A7: TC.TR.JIMFEEDBACK.006 | B7: #36090 | D7: Sokongan / Kelulusan no of row | F7: Check on the first Column before Nama Pengguna | G7: 1. Login 2. Click on Pengurusan Pengguna 3. Click on Sokongan Permohonan ID 4. Observe Repeat with Kelulusan Permohonan ID and observe | I7: Column No. is added | J7: PASS | M7: YHUVAN / LUQMAN
A8: TC.TR.JIMFEEDBACK.007 | B8: #36091 | D8: Pendaftaran Pengguna Baharu | F8: Check on error message for email missing | G8: 1. Click on daftar 2. Fill all the details needed except email 3. Click Hantar 4. Observe | I8: Eng. Email Address is required MY. Alamat Emel diperlukan | J8: PASS | M8: YHUVAN / LUQMAN
A9: TC.TR.JIMFEEDBACK.008 | D9: Pendaftaran Pengguna Baharu | F9: Check on error message for email missing | G9: 1. Click on daftar 2. Fill all the details needed except email 3. Filled in email without following format 4. Observe | I9: Error message display *kindly check for both language | J9: PASS | M9: YHUVAN / LUQMAN
A10: TC.TR.JIMFEEDBACK.009 | B10: #36092 | D10: Redirect to screen Sokongan / Kelulusan once success claim | F10: Check on once user claim the application, it will redirect the user to Sokongan / Kelulusan Permohonan ID page | G10: 1. Login 2. Click on Pengurusan Pengguna 3. Click on Sokongan Permohonan ID 4. Click on '…' column tindakan and click claim 5. Observe Repeat with Kelulusan Permohonan ID and observe | I10: Redirect to screen Sokongan / Kelulusan once success claim | J10: PASS | M10: YHUVAN / LUQMAN
A11: TC.TR.JIMFEEDBACK.010 | B11: #36093 | D11: Add table Maklumat Peranan Pengguna | F11: Check on Table Maklumat Peranan Pengguna | G11: 1. Click on daftar 2. Select Jabatan/Agensi and Peranan pengguna 3. Observe the Maklumat Peranan Pengguna must be mapped according to the excel given *Repeat all the process to each available Jabatan/Agensi and Peranan Pengguna | I11: Mapped accordingly, refer excel Automation akan cover most of the part | J11: PASS | K11: #37410 | M11: YHUVAN / LUQMAN
A12: TC.TR.JIMFEEDBACK.011 | B12: #36094 | D12: Sokongan / Kelulusan - auto release | E12: SELECT * FROM sppa_env2.PRE_IDM_PROFILE; EDR_CLAIM_BY - SOKONGAN EDR_CLAIM_DT - SOKONGAN APR_CLAIM_BY - KELULUSAN APR_CLAIM_DT - KELULUSAN all of these column will NULL after 4 days | F12: Check on Sokongan / Kelulusan auto release after 4 days without any action done by the user | G12: 1. Login 2. Click on Pengurusan Pengguna 3. Click on Sokongan Permohonan ID 4. Click on '…' column tindakan and click claim 5. Change the date of the application to be after 4 days after claim and observe Repeat with Kelulusan Permohonan ID and observe | I12: Application has been auto release and user need to claim once again | J12: PASS | M12: YHUVAN / LUQMAN
A13: TC.TR.JIMFEEDBACK.012 | D13: Sokongan / Kelulusan - auto release | E13: SELECT * FROM sppa_env2.PRE_IDM_PROFILE; EDR_CLAIM_BY - SOKONGAN EDR_CLAIM_DT - SOKONGAN APR_CLAIM_BY - KELULUSAN APR_CLAIM_DT - KELULUSAN all of these column will not be NULL after 3 days | F13: Check on Sokongan / Kelulusan auto release afte 3 days without any action done by the user | G13: 1. Login 2. Click on Pengurusan Pengguna 3. Click on Sokongan Permohonan ID 4. Click on '…' column tindakan and click claim 5. Change the date of the application to be after 3 days after claim and observe Repeat with Kelulusan Permohonan ID and observe | I13: Application is still on user hand | J13: PASS | M13: YHUVAN / LUQMAN
A14: TC.TR.JIMFEEDBACK.013 | D14: Sokongan / Kelulusan - auto release | E14: SELECT * FROM sppa_env2.PRE_IDM_PROFILE; EDR_CLAIM_BY - SOKONGAN EDR_CLAIM_DT - SOKONGAN APR_CLAIM_BY - KELULUSAN APR_CLAIM_DT - KELULUSAN all of these column will NULL after 5 days | F14: Check on Sokongan / Kelulusan auto release after 5 days without any action done by the user | G14: 1. Login 2. Click on Pengurusan Pengguna 3. Click on Sokongan Permohonan ID 4. Click on '…' column tindakan and click claim 5. Change the date of the application to be after 5 days after claim and observe Repeat with Kelulusan Permohonan ID and observe | I14: Application has been auto release and user need to claim once again | J14: PASS | M14: YHUVAN / LUQMAN
A15: TC.TR.JIMFEEDBACK.014 | B15: #36509 | D15: Change Description JIM SECURITY ADMIN | E15: PRE_REG_IND = NULL changed it to Y for the selected role SELECT * FROM sppa_env2.IDM_USER_GROUP; | F15: Check on description for JIM SECURITY ADMIN has been change to JIM ENTRY POINT ADMIN | G15: 1. Click on daftar 2. Filled all required fills and Select JIM as Jabatan/Agensi 3. Observe the Peranan Pengguna, JIM SECURITY ADMIN must be changed to JIM ENTRY POINT ADMIN | I15: JIM SECURITY ADMIN must be changed to JIM ENTRY POINT ADMIN Kindly check in DB as well SELECT * FROM sppa_env2.IDM_USER_GROUP; | J15: PASS | M15: YHUVAN / LUQMAN
A16: TC.TR.JIMFEEDBACK.015 | D16: Create data from daftar until kelulusan | E16: JIM ADMIN JIM SECURITY ADMIN JIM OPERATOR JIM SUPERVISOR BPA ADMIN BPA HQ BPA STATE BPA BRANCH | F16: Check on data has been successfully created without error | G16: 1. Create data for OSC user one and JIM user one (Manual) 2. Create data for all JIM using automation Repeat for all JIM User | I16: Data Successfully created and can be login in without any issue | J16: PASS | M16: YHUVAN / LUQMAN

Sheet #37022
A1: Case ID | B1: Redmine User Story | C1: Tracker | D1: Scenario | E1: Pre Condition | F1: Case | G1: Steps | H1: Test Data | I1: Expected Result | J1: Result | K1: Redmine Defect | L1: Additional/Comments/Issues | M1: QA PIC | N1: =SUM(N2:N140) -> 66 | O1: =SUM(O2:O140) -> 0 | P1: =SUM(P2:P140) -> 0 | Q1: =SUM(Q2:Q140) -> 0 | R1: =SUM(R2:R140) -> 0
A2: JABATAN KDN | N2: =COUNTIF($J3:J3,"PASS") -> 1 | O2: =COUNTIF($J3:J3,"FAIL") -> 0 | P2: =COUNTBLANK(J3:J3) -> 0 | Q2: =COUNTIF($J3:J3,"IN PROGRESS") -> 0 | R2: =COUNTIF($J3:J3,"BLOCKED") -> 0
A3: TC.TR.IDM.JAWATAN.001 | B3: #37022 | C3: User Story | D3: Pendaftaran Pengguna Baru - Jawatan (Mandatory for all level) | E3: KDN ADMIN | F3: Check all Jawatan Listings in Borang Online and Pindah Lokasi Pengguna | G3: 1) Click on Pendaftaran Pengguna 2) Fill in all relevant user details. 3) Choose KDN as Jabatan 4) Verify all the jawatan for each peranaan under the respective Jabatan | I3: SETIAUSAHA BAHAGIAN SETIAUSAHA PEJABAT TIMBALAN SETIAUSAHA BAHAGIAN PEMBANTU SETIAUSAHA PEJABAT TIMBALAN SETIAUSAHA BAHAGIAN (UNIT OSC PEKERJA ASING) SETIAUSAHA PEJABAT (UNIT OSC PEKERJA ASING) KETUA PENOLONG SETIAUSAHA (UNIT OPERASI) PENOLONG SETIAUSAHA (UNIT OPERASI) PENOLONG PEGAWAI TADBIR (UNIT OPERASI) PEMBANTU OPERASI (UNIT OPERASI) | J3: PASS | M3: YHUVAN
A4: JABATAN OSC | N4: =COUNTIF($J5:J7,"PASS") -> 3 | O4: =COUNTIF($J5:J7,"FAIL") -> 0 | P4: =COUNTBLANK(J5:J7) -> 0 | Q4: =COUNTIF($J5:J7,"IN PROGRESS") -> 0 | R4: =COUNTIF($J5:J7,"BLOCKED") -> 0
A5: TC.TR.IDM.JAWATAN.002 | B5: #37022 | C5: User Story | D5: Pendaftaran Pengguna Baru - Jawatan (Mandatory for all level) | E5: OSC ADMIN | F5: Check all Jawatan Listings in Borang Online and Pindah Lokasi Pengguna | G5: 1) Click on Pendaftaran Pengguna 2) Fill in all relevant user details. 3) Choose OSC as Jabatan 4) Verify all the jawatan for each peranaan under the respective Jabatan | I5: SETIAUSAHA BAHAGIAN SETIAUSAHA PEJABAT TIMBALAN SETIAUSAHA BAHAGIAN PEMBANTU SETIAUSAHA PEJABAT TIMBALAN SETIAUSAHA BAHAGIAN (UNIT OSC PEKERJA ASING) SETIAUSAHA PEJABAT (UNIT OSC PEKERJA ASING) KETUA PENOLONG SETIAUSAHA (UNIT OPERASI) PENOLONG SETIAUSAHA (UNIT OPERASI) PENOLONG PEGAWAI TADBIR (UNIT OPERASI) PEMBANTU OPERASI (UNIT OPERASI) | J5: PASS | M5: YHUVAN
A6: TC.TR.IDM.JAWATAN.003 | D6: Pendaftaran Pengguna Baru - Jawatan (Mandatory for all level) | E6: OSC OFFICER ADMIN | F6: Check all Jawatan Listings in Borang Online and Pindah Lokasi Pengguna | G6: 1) Click on Pendaftaran Pengguna 2) Fill in all relevant user details. 3) Choose OSC as Jabatan 4) Verify all the jawatan for each peranaan under the respective Jabatan | I6: SETIAUSAHA BAHAGIAN SETIAUSAHA PEJABAT TIMBALAN SETIAUSAHA BAHAGIAN PEMBANTU SETIAUSAHA PEJABAT TIMBALAN SETIAUSAHA BAHAGIAN (UNIT OSC PEKERJA ASING) SETIAUSAHA PEJABAT (UNIT OSC PEKERJA ASING) KETUA PENOLONG SETIAUSAHA (UNIT OPERASI) PENOLONG SETIAUSAHA (UNIT OPERASI) PENOLONG PEGAWAI TADBIR (UNIT OPERASI) PEMBANTU OPERASI (UNIT OPERASI) | J6: PASS | M6: YHUVAN
A7: TC.TR.IDM.JAWATAN.004 | D7: Pendaftaran Pengguna Baru - Jawatan (Mandatory for all level) | E7: OSC PT | F7: Check all Jawatan Listings in Borang Online and Pindah Lokasi Pengguna | G7: 1) Click on Pendaftaran Pengguna 2) Fill in all relevant user details. 3) Choose OSC as Jabatan 4) Verify all the jawatan for each peranaan under the respective Jabatan | I7: SETIAUSAHA BAHAGIAN SETIAUSAHA PEJABAT TIMBALAN SETIAUSAHA BAHAGIAN PEMBANTU SETIAUSAHA PEJABAT TIMBALAN SETIAUSAHA BAHAGIAN (UNIT OSC PEKERJA ASING) SETIAUSAHA PEJABAT (UNIT OSC PEKERJA ASING) KETUA PENOLONG SETIAUSAHA (UNIT OPERASI) PENOLONG SETIAUSAHA (UNIT OPERASI) PENOLONG PEGAWAI TADBIR (UNIT OPERASI) PEMBANTU OPERASI (UNIT OPERASI) | J7: PASS | M7: YHUVAN
A8: JABATAN AKS | N8: =COUNTIF($J9:J17,"PASS") -> 9 | O8: =COUNTIF($J9:J17,"FAIL") -> 0 | P8: =COUNTBLANK(J9:J17) -> 0 | Q8: =COUNTIF($J9:J17,"IN PROGRESS") -> 0 | R8: =COUNTIF($J9:J17,"BLOCKED") -> 0
A9: TC.TR.IDM.JAWATAN.005 | B9: #37022 | C9: User Story | D9: Pendaftaran Pengguna Baru - Jawatan (Mandatory for all level) | E9: CIDB USER | F9: Check all Jawatan Listings in Borang Online and Pindah Lokasi Pengguna | G9: 1) Click on Pendaftaran Pengguna 2) Fill in all relevant user details. 3) Choose AKS as Jabatan 4) Verify all the jawatan for each peranaan under the respective Jabatan | I9: KETUA PEGAWAI EKSEKUTIF TIMBALAN KETUA PEGAWAI EKSEKUTIF PENGARAH TIMBALAN PENGARAH PENGURUS PENOLONG PENGURUS PEGAWAI TADBIR PEGAWAI CIDB PEGAWAI VERIFIKASI PENOLONG PEGAWAI TADBIR PEMBANTU TADBIR (AM / KEWANGAN) PEMBANTU OPERASI PEGAWAI KAUNTER CIDB | J9: PASS | M9: YHUVAN
A10: TC.TR.IDM.JAWATAN.006 | D10: Pendaftaran Pengguna Baru - Jawatan (Mandatory for all level) | E10: MITI USER | F10: Check all Jawatan Listings in Borang Online and Pindah Lokasi Pengguna | G10: 1) Click on Pendaftaran Pengguna 2) Fill in all relevant user details. 3) Choose AKS as Jabatan 4) Verify all the jawatan for each peranaan under the respective Jabatan | I10: PEGAWAI MITI PENGARAH TIMBALAN PENGARAH PTD PEGAWAI TEKNIKAL PEGAWAI PENTADBIRAN PEGAWAI PENGUAT KUASA | J10: PASS | M10: YHUVAN
A11: TC.TR.IDM.JAWATAN.007 | D11: Pendaftaran Pengguna Baru - Jawatan (Mandatory for all level) | E11: KPK USER | F11: Check all Jawatan Listings in Borang Online and Pindah Lokasi Pengguna | G11: 1) Click on Pendaftaran Pengguna 2) Fill in all relevant user details. 3) Choose AKS as Jabatan 4) Verify all the jawatan for each peranaan under the respective Jabatan | I11: PEGAWAI KPK PENGARAH TIMBALAN PENGARAH PTD PEGAWAI TEKNIKAL PEGAWAI PENTADBIRAN PEGAWAI PENGUAT KUASA | J11: PASS | M11: YHUVAN
A12: TC.TR.IDM.JAWATAN.008 | D12: Pendaftaran Pengguna Baru - Jawatan (Mandatory for all level) | E12: KPKM USER | F12: Check all Jawatan Listings in Borang Online and Pindah Lokasi Pengguna | G12: 1) Click on Pendaftaran Pengguna 2) Fill in all relevant user details. 3) Choose AKS as Jabatan 4) Verify all the jawatan for each peranaan under the respective Jabatan | I12: PEGAWAI KPKM PENGARAH TIMBALAN PENGARAH PTD PEGAWAI TEKNIKAL PEGAWAI PENTADBIRAN PEGAWAI PENGUAT KUASA | J12: PASS | M12: YHUVAN
A13: TC.TR.IDM.JAWATAN.009 | D13: Pendaftaran Pengguna Baru - Jawatan (Mandatory for all level) | E13: NRES USER | F13: Check all Jawatan Listings in Borang Online and Pindah Lokasi Pengguna | G13: 1) Click on Pendaftaran Pengguna 2) Fill in all relevant user details. 3) Choose AKS as Jabatan 4) Verify all the jawatan for each peranaan under the respective Jabatan | I13: PEGAWAI NRES PENGARAH TIMBALAN PENGARAH PTD PEGAWAI TEKNIKAL PEGAWAI PENTADBIRAN PEGAWAI PENGUAT KUASA | J13: PASS | M13: YHUVAN
A14: TC.TR.IDM.JAWATAN.010 | D14: Pendaftaran Pengguna Baru - Jawatan (Mandatory for all level) | E14: KPDN USER | F14: Check all Jawatan Listings in Borang Online and Pindah Lokasi Pengguna | G14: 1) Click on Pendaftaran Pengguna 2) Fill in all relevant user details. 3) Choose AKS as Jabatan 4) Verify all the jawatan for each peranaan under the respective Jabatan | I14: PEGAWAI KPDN PENGARAH TIMBALAN PENGARAH PTD PEGAWAI TEKNIKAL PEGAWAI PENTADBIRAN PEGAWAI PENGUAT KUASA | J14: PASS | M14: YHUVAN
A15: TC.TR.IDM.JAWATAN.011 | D15: Pendaftaran Pengguna Baru - Jawatan (Mandatory for all level) | E15: MOT USER | F15: Check all Jawatan Listings in Borang Online and Pindah Lokasi Pengguna | G15: 1) Click on Pendaftaran Pengguna 2) Fill in all relevant user details. 3) Choose AKS as Jabatan 4) Verify all the jawatan for each peranaan under the respective Jabatan | I15: PEGAWAI MOT PENGARAH TIMBALAN PENGARAH PTD PEGAWAI TEKNIKAL PEGAWAI PENTADBIRAN PEGAWAI PENGUAT KUASA | J15: PASS | M15: YHUVAN
A16: TC.TR.IDM.JAWATAN.012 | D16: Pendaftaran Pengguna Baru - Jawatan (Mandatory for all level) | E16: MOTAC USER | F16: Check all Jawatan Listings in Borang Online and Pindah Lokasi Pengguna | G16: 1) Click on Pendaftaran Pengguna 2) Fill in all relevant user details. 3) Choose AKS as Jabatan 4) Verify all the jawatan for each peranaan under the respective Jabatan | I16: PEGAWAI MOTAC PENGARAH TIMBALAN PENGARAH PTD PEGAWAI TEKNIKAL PEGAWAI PENTADBIRAN PEGAWAI PENGUAT KUASA | J16: PASS | M16: YHUVAN
A17: TC.TR.IDM.JAWATAN.013 | D17: Pendaftaran Pengguna Baru - Jawatan (Mandatory for all level) | E17: KDN USER | F17: Check all Jawatan Listings in Borang Online and Pindah Lokasi Pengguna | G17: 1) Click on Pendaftaran Pengguna 2) Fill in all relevant user details. 3) Choose AKS as Jabatan 4) Verify all the jawatan for each peranaan under the respective Jabatan | I17: PEGAWAI KDN PENGARAH TIMBALAN PENGARAH PTD PEGAWAI TEKNIKAL PEGAWAI PENTADBIRAN PEGAWAI PENGUAT KUASA | J17: PASS | M17: YHUVAN
A18: JABATAN JIM | N18: =COUNTIF($J19:J31,"PASS") -> 13 | O18: =COUNTIF($J19:J31,"FAIL") -> 0 | P18: =COUNTBLANK(J19:J31) -> 0 | Q18: =COUNTIF($J19:J31,"IN PROGRESS") -> 0 | R18: =COUNTIF($J19:J31,"BLOCKED") -> 0
A19: TC.TR.IDM.JAWATAN.014 | B19: #37022 | C19: User Story | D19: Pendaftaran Pengguna Baru - Jawatan (Mandatory for all level) | E19: JIM ADMIN | F19: Check all Jawatan Listings in Borang Online and Pindah Lokasi Pengguna | G19: 1) Click on Pendaftaran Pengguna 2) Fill in all relevant user details. 3) Choose JIM as Jabatan 4) Verify all the jawatan for each peranaan under the respective Jabatan | I19: PEGAWAI IMIGRESEN PENGARAH TIMBALAN PENGARAH KETUA BAHAGIAN PEGAWAI TADBIR DAN DIPLOMATIK (PTD) PEGAWAI KESELAMATAN PEGAWAI PENGUAT KUASA PEGAWAI PEMERIKSA IMIGRESEN PEGAWAI OPERASI PEGAWAI TEKNOLOGI MAKLUMAT PEGAWAI KHIDMAT PELANGGAN | J19: PASS | M19: YHUVAN
A20: TC.TR.IDM.JAWATAN.015 | D20: Pendaftaran Pengguna Baru - Jawatan (Mandatory for all level) | E20: BPA ADMIN | F20: Check all Jawatan Listings in Borang Online and Pindah Lokasi Pengguna | G20: 1) Click on Pendaftaran Pengguna 2) Fill in all relevant user details. 3) Choose JIM as Jabatan 4) Verify all the jawatan for each peranaan under the respective Jabatan | I20: PEGAWAI IMIGRESEN PENGARAH TIMBALAN PENGARAH KETUA BAHAGIAN PEGAWAI TADBIR DAN DIPLOMATIK (PTD) PEGAWAI KESELAMATAN PEGAWAI PENGUAT KUASA PEGAWAI PEMERIKSA IMIGRESEN PEGAWAI OPERASI PEGAWAI TEKNOLOGI MAKLUMAT PEGAWAI KHIDMAT PELANGGAN | J20: PASS | M20: YHUVAN
A21: TC.TR.IDM.JAWATAN.016 | D21: Pendaftaran Pengguna Baru - Jawatan (Mandatory for all level) | E21: BPA HQ | F21: Check all Jawatan Listings in Borang Online and Pindah Lokasi Pengguna | G21: 1) Click on Pendaftaran Pengguna 2) Fill in all relevant user details. 3) Choose JIM as Jabatan 4) Verify all the jawatan for each peranaan under the respective Jabatan | I21: PEGAWAI IMIGRESEN PENGARAH TIMBALAN PENGARAH KETUA BAHAGIAN PEGAWAI TADBIR DAN DIPLOMATIK (PTD) PEGAWAI KESELAMATAN PEGAWAI PENGUAT KUASA PEGAWAI PEMERIKSA IMIGRESEN PEGAWAI OPERASI PEGAWAI TEKNOLOGI MAKLUMAT PEGAWAI KHIDMAT PELANGGAN | J21: PASS | M21: YHUVAN
A22: TC.TR.IDM.JAWATAN.017 | D22: Pendaftaran Pengguna Baru - Jawatan (Mandatory for all level) | E22: BPA STATE | F22: Check all Jawatan Listings in Borang Online and Pindah Lokasi Pengguna | G22: 1) Click on Pendaftaran Pengguna 2) Fill in all relevant user details. 3) Choose JIM as Jabatan 4) Verify all the jawatan for each peranaan under the respective Jabatan | I22: PEGAWAI IMIGRESEN PENGARAH TIMBALAN PENGARAH KETUA BAHAGIAN PEGAWAI TADBIR DAN DIPLOMATIK (PTD) PEGAWAI KESELAMATAN PEGAWAI PENGUAT KUASA PEGAWAI PEMERIKSA IMIGRESEN PEGAWAI OPERASI PEGAWAI TEKNOLOGI MAKLUMAT PEGAWAI KHIDMAT PELANGGAN | J22: PASS | M22: YHUVAN
A23: TC.TR.IDM.JAWATAN.018 | D23: Pendaftaran Pengguna Baru - Jawatan (Mandatory for all level) | E23: BPA BRANCH | F23: Check all Jawatan Listings in Borang Online and Pindah Lokasi Pengguna | G23: 1) Click on Pendaftaran Pengguna 2) Fill in all relevant user details. 3) Choose JIM as Jabatan 4) Verify all the jawatan for each peranaan under the respective Jabatan | I23: PEGAWAI IMIGRESEN PENGARAH TIMBALAN PENGARAH KETUA BAHAGIAN PEGAWAI TADBIR DAN DIPLOMATIK (PTD) PEGAWAI KESELAMATAN PEGAWAI PENGUAT KUASA PEGAWAI PEMERIKSA IMIGRESEN PEGAWAI OPERASI PEGAWAI TEKNOLOGI MAKLUMAT PEGAWAI KHIDMAT PELANGGAN | J23: PASS | M23: YHUVAN
A24: TC.TR.IDM.JAWATAN.019 | D24: Pendaftaran Pengguna Baru - Jawatan (Mandatory for all level) | E24: ENFORCEMENT ADMIN | F24: Check all Jawatan Listings in Borang Online and Pindah Lokasi Pengguna | G24: 1) Click on Pendaftaran Pengguna 2) Fill in all relevant user details. 3) Choose JIM as Jabatan 4) Verify all the jawatan for each peranaan under the respective Jabatan | I24: PEGAWAI IMIGRESEN PENGARAH TIMBALAN PENGARAH KETUA BAHAGIAN PEGAWAI TADBIR DAN DIPLOMATIK (PTD) PEGAWAI KESELAMATAN PEGAWAI PENGUAT KUASA PEGAWAI PEMERIKSA IMIGRESEN PEGAWAI OPERASI PEGAWAI TEKNOLOGI MAKLUMAT PEGAWAI KHIDMAT PELANGGAN | J24: PASS | M24: YHUVAN
A25: TC.TR.IDM.JAWATAN.020 | D25: Pendaftaran Pengguna Baru - Jawatan (Mandatory for all level) | E25: ENFORCEMENT USER (PUTRAJAYA) | F25: Check all Jawatan Listings in Borang Online and Pindah Lokasi Pengguna | G25: 1) Click on Pendaftaran Pengguna 2) Fill in all relevant user details. 3) Choose JIM as Jabatan 4) Verify all the jawatan for each peranaan under the respective Jabatan | I25: PEGAWAI IMIGRESEN PENGARAH TIMBALAN PENGARAH KETUA BAHAGIAN PEGAWAI TADBIR DAN DIPLOMATIK (PTD) PEGAWAI KESELAMATAN PEGAWAI PENGUAT KUASA PEGAWAI PEMERIKSA IMIGRESEN PEGAWAI OPERASI PEGAWAI TEKNOLOGI MAKLUMAT PEGAWAI KHIDMAT PELANGGAN | J25: PASS | M25: YHUVAN
A26: TC.TR.IDM.JAWATAN.021 | D26: Pendaftaran Pengguna Baru - Jawatan (Mandatory for all level) | E26: ENFORCEMENT MOBILE ADMIN | F26: Check all Jawatan Listings in Borang Online and Pindah Lokasi Pengguna | G26: 1) Click on Pendaftaran Pengguna 2) Fill in all relevant user details. 3) Choose JIM as Jabatan 4) Verify all the jawatan for each peranaan under the respective Jabatan | I26: PEGAWAI IMIGRESEN PENGARAH TIMBALAN PENGARAH KETUA BAHAGIAN PEGAWAI TADBIR DAN DIPLOMATIK (PTD) PEGAWAI KESELAMATAN PEGAWAI PENGUAT KUASA PEGAWAI PEMERIKSA IMIGRESEN PEGAWAI OPERASI PEGAWAI TEKNOLOGI MAKLUMAT PEGAWAI KHIDMAT PELANGGAN | J26: PASS | M26: YHUVAN
A27: TC.TR.IDM.JAWATAN.022 | D27: Pendaftaran Pengguna Baru - Jawatan (Mandatory for all level) | E27: ENFORCEMENT STATE ADMIN | F27: Check all Jawatan Listings in Borang Online and Pindah Lokasi Pengguna | G27: 1) Click on Pendaftaran Pengguna 2) Fill in all relevant user details. 3) Choose JIM as Jabatan 4) Verify all the jawatan for each peranaan under the respective Jabatan | I27: PEGAWAI IMIGRESEN PENGARAH TIMBALAN PENGARAH KETUA BAHAGIAN PEGAWAI TADBIR DAN DIPLOMATIK (PTD) PEGAWAI KESELAMATAN PEGAWAI PENGUAT KUASA PEGAWAI PEMERIKSA IMIGRESEN PEGAWAI OPERASI PEGAWAI TEKNOLOGI MAKLUMAT PEGAWAI KHIDMAT PELANGGAN | J27: PASS | M27: YHUVAN
A28: TC.TR.IDM.JAWATAN.023 | D28: Pendaftaran Pengguna Baru - Jawatan (Mandatory for all level) | E28: ENFORCEMENT STATE USER | F28: Check all Jawatan Listings in Borang Online and Pindah Lokasi Pengguna | G28: 1) Click on Pendaftaran Pengguna 2) Fill in all relevant user details. 3) Choose JIM as Jabatan 4) Verify all the jawatan for each peranaan under the respective Jabatan | I28: PEGAWAI IMIGRESEN PENGARAH TIMBALAN PENGARAH KETUA BAHAGIAN PEGAWAI TADBIR DAN DIPLOMATIK (PTD) PEGAWAI KESELAMATAN PEGAWAI PENGUAT KUASA PEGAWAI PEMERIKSA IMIGRESEN PEGAWAI OPERASI PEGAWAI TEKNOLOGI MAKLUMAT PEGAWAI KHIDMAT PELANGGAN | J28: PASS | M28: YHUVAN
A29: TC.TR.IDM.JAWATAN.024 | D29: Pendaftaran Pengguna Baru - Jawatan (Mandatory for all level) | E29: JIM ENTRY POINT ADMIN | F29: Check all Jawatan Listings in Borang Online and Pindah Lokasi Pengguna | G29: 1) Click on Pendaftaran Pengguna 2) Fill in all relevant user details. 3) Choose JIM as Jabatan 4) Verify all the jawatan for each peranaan under the respective Jabatan | I29: PEGAWAI IMIGRESEN PENGARAH TIMBALAN PENGARAH KETUA BAHAGIAN PEGAWAI TADBIR DAN DIPLOMATIK (PTD) PEGAWAI KESELAMATAN PEGAWAI PENGUAT KUASA PEGAWAI PEMERIKSA IMIGRESEN PEGAWAI OPERASI PEGAWAI TEKNOLOGI MAKLUMAT PEGAWAI KHIDMAT PELANGGAN | J29: PASS | M29: YHUVAN
A30: TC.TR.IDM.JAWATAN.025 | D30: Pendaftaran Pengguna Baru - Jawatan (Mandatory for all level) | E30: JIM SUPERVISOR | F30: Check all Jawatan Listings in Borang Online and Pindah Lokasi Pengguna | G30: 1) Click on Pendaftaran Pengguna 2) Fill in all relevant user details. 3) Choose JIM as Jabatan 4) Verify all the jawatan for each peranaan under the respective Jabatan | I30: PEGAWAI IMIGRESEN PENGARAH TIMBALAN PENGARAH KETUA BAHAGIAN PEGAWAI TADBIR DAN DIPLOMATIK (PTD) PEGAWAI KESELAMATAN PEGAWAI PENGUAT KUASA PEGAWAI PEMERIKSA IMIGRESEN PEGAWAI OPERASI PEGAWAI TEKNOLOGI MAKLUMAT PEGAWAI KHIDMAT PELANGGAN | J30: PASS | M30: YHUVAN
A31: TC.TR.IDM.JAWATAN.026 | D31: Pendaftaran Pengguna Baru - Jawatan (Mandatory for all level) | E31: JIM OPERATOR | F31: Check all Jawatan Listings in Borang Online and Pindah Lokasi Pengguna | G31: 1) Click on Pendaftaran Pengguna 2) Fill in all relevant user details. 3) Choose JIM as Jabatan 4) Verify all the jawatan for each peranaan under the respective Jabatan | I31: PEGAWAI IMIGRESEN PENGARAH TIMBALAN PENGARAH KETUA BAHAGIAN PEGAWAI TADBIR DAN DIPLOMATIK (PTD) PEGAWAI KESELAMATAN PEGAWAI PENGUAT KUASA PEGAWAI PEMERIKSA IMIGRESEN PEGAWAI OPERASI PEGAWAI TEKNOLOGI MAKLUMAT PEGAWAI KHIDMAT PELANGGAN | J31: PASS | M31: YHUVAN
A32: JABATAN KDNKK | N32: =COUNTIF($J33:J40,"PASS") -> 8 | O32: =COUNTIF($J33:J40,"FAIL") -> 0 | P32: =COUNTBLANK(J33:J40) -> 0 | Q32: =COUNTIF($J33:J40,"IN PROGRESS") -> 0 | R32: =COUNTIF($J33:J40,"BLOCKED") -> 0
A33: TC.TR.IDM.JAWATAN.027 | B33: #37022 | C33: User Story | D33: Pendaftaran Pengguna Baru - Jawatan (Mandatory for all level) | E33: KDN SECURITY ADMIN | F33: Check all Jawatan Listings in Borang Online and Pindah Lokasi Pengguna | G33: 1) Click on Pendaftaran Pengguna 2) Fill in all relevant user details. 3) Choose KDNKK as Jabatan 4) Verify all the jawatan for each peranaan under the respective Jabatan | I33: PEGAWAI KDN PEGAWAI KESELAMATAN PENGARAH TIMBALAN PENGARAH KETUA BAHAGIAN PEGAWAI TADBIR DAN DIPLOMATIK (PTD) PEGAWAI PENGUAT KUASA PEGAWAI PENYIASAT PEGAWAI OPERASI PEGAWAI TEKNOLOGI MAKLUMAT | J33: PASS | M33: YHUVAN
A34: TC.TR.IDM.JAWATAN.028 | D34: Pendaftaran Pengguna Baru - Jawatan (Mandatory for all level) | E34: KDN SECURITY OPERATOR | F34: Check all Jawatan Listings in Borang Online and Pindah Lokasi Pengguna | G34: 1) Click on Pendaftaran Pengguna 2) Fill in all relevant user details. 3) Choose KDNKK as Jabatan 4) Verify all the jawatan for each peranaan under the respective Jabatan | I34: PEGAWAI KDN PEGAWAI KESELAMATAN PENGARAH TIMBALAN PENGARAH KETUA BAHAGIAN PEGAWAI TADBIR DAN DIPLOMATIK (PTD) PEGAWAI PENGUAT KUASA PEGAWAI PENYIASAT PEGAWAI OPERASI PEGAWAI TEKNOLOGI MAKLUMAT | J34: PASS | M34: YHUVAN
A35: TC.TR.IDM.JAWATAN.029 | D35: Pendaftaran Pengguna Baru - Jawatan (Mandatory for all level) | E35: KDNKK APPROVER | F35: Check all Jawatan Listings in Borang Online and Pindah Lokasi Pengguna | G35: 1) Click on Pendaftaran Pengguna 2) Fill in all relevant user details. 3) Choose KDNKK as Jabatan 4) Verify all the jawatan for each peranaan under the respective Jabatan | I35: PEGAWAI KDN PEGAWAI KESELAMATAN PENGARAH TIMBALAN PENGARAH KETUA BAHAGIAN PEGAWAI TADBIR DAN DIPLOMATIK (PTD) PEGAWAI PENGUAT KUASA PEGAWAI PENYIASAT PEGAWAI OPERASI PEGAWAI TEKNOLOGI MAKLUMAT | J35: PASS | M35: YHUVAN
A36: TC.TR.IDM.JAWATAN.030 | D36: Pendaftaran Pengguna Baru - Jawatan (Mandatory for all level) | E36: KDNKK OPERATOR | F36: Check all Jawatan Listings in Borang Online and Pindah Lokasi Pengguna | G36: 1) Click on Pendaftaran Pengguna 2) Fill in all relevant user details. 3) Choose KDNKK as Jabatan 4) Verify all the jawatan for each peranaan under the respective Jabatan | I36: PEGAWAI KDN PEGAWAI KESELAMATAN PENGARAH TIMBALAN PENGARAH KETUA BAHAGIAN PEGAWAI TADBIR DAN DIPLOMATIK (PTD) PEGAWAI PENGUAT KUASA PEGAWAI PENYIASAT PEGAWAI OPERASI PEGAWAI TEKNOLOGI MAKLUMAT | J36: PASS | K36: #38148 | L36: KDNKK operator option is not available in Borang Online dropdown Waiting for Kak Ain to confirm | M36: YHUVAN
A37: TC.TR.IDM.JAWATAN.031 | D37: Pendaftaran Pengguna Baru - Jawatan (Mandatory for all level) | E37: KDNKK APPROVER AND OPERATOR | F37: Check all Jawatan Listings in Borang Online and Pindah Lokasi Pengguna | G37: 1) Click on Pendaftaran Pengguna 2) Fill in all relevant user details. 3) Choose KDNKK as Jabatan 4) Verify all the jawatan for each peranaan under the respective Jabatan | I37: PEGAWAI KDN PEGAWAI KESELAMATAN PENGARAH TIMBALAN PENGARAH KETUA BAHAGIAN PEGAWAI TADBIR DAN DIPLOMATIK (PTD) PEGAWAI PENGUAT KUASA PEGAWAI PENYIASAT PEGAWAI OPERASI PEGAWAI TEKNOLOGI MAKLUMAT | J37: PASS | M37: YHUVAN
A38: TC.TR.IDM.JAWATAN.032 | D38: Pendaftaran Pengguna Baru - Jawatan (Mandatory for all level) | E38: KDNKK SUPERSIVOR | F38: Check all Jawatan Listings in Borang Online and Pindah Lokasi Pengguna | G38: 1) Click on Pendaftaran Pengguna 2) Fill in all relevant user details. 3) Choose KDNKK as Jabatan 4) Verify all the jawatan for each peranaan under the respective Jabatan | I38: PEGAWAI KDN PEGAWAI KESELAMATAN PENGARAH TIMBALAN PENGARAH KETUA BAHAGIAN PEGAWAI TADBIR DAN DIPLOMATIK (PTD) PEGAWAI PENGUAT KUASA PEGAWAI PENYIASAT PEGAWAI OPERASI PEGAWAI TEKNOLOGI MAKLUMAT | J38: PASS | M38: YHUVAN
A39: TC.TR.IDM.JAWATAN.033 | D39: Pendaftaran Pengguna Baru - Jawatan (Mandatory for all level) | E39: KDNKK VERIFIER | F39: Check all Jawatan Listings in Borang Online and Pindah Lokasi Pengguna | G39: 1) Click on Pendaftaran Pengguna 2) Fill in all relevant user details. 3) Choose KDNKK as Jabatan 4) Verify all the jawatan for each peranaan under the respective Jabatan | I39: PEGAWAI KDN PEGAWAI KESELAMATAN PENGARAH TIMBALAN PENGARAH KETUA BAHAGIAN PEGAWAI TADBIR DAN DIPLOMATIK (PTD) PEGAWAI PENGUAT KUASA PEGAWAI PENYIASAT PEGAWAI OPERASI PEGAWAI TEKNOLOGI MAKLUMAT | J39: PASS | M39: YHUVAN
A40: TC.TR.IDM.JAWATAN.034 | D40: Pendaftaran Pengguna Baru - Jawatan (Mandatory for all level) | E40: KDNKK EQM APPROVER | F40: Check all Jawatan Listings in Borang Online and Pindah Lokasi Pengguna | G40: 1) Click on Pendaftaran Pengguna 2) Fill in all relevant user details. 3) Choose KDNKK as Jabatan 4) Verify all the jawatan for each peranaan under the respective Jabatan | I40: PEGAWAI KDN PEGAWAI KESELAMATAN PENGARAH TIMBALAN PENGARAH KETUA BAHAGIAN PEGAWAI TADBIR DAN DIPLOMATIK (PTD) PEGAWAI PENGUAT KUASA PEGAWAI PENYIASAT PEGAWAI OPERASI PEGAWAI TEKNOLOGI MAKLUMAT | J40: PASS | M40: YHUVAN
...

Sheet IDM - KDNK
A1: Case ID | B1: Redmine User Story | C1: Tracker | D1: Scenario | E1: Pre Condition | F1: Case | G1: Steps | H1: Test Data | I1: Expected Result | J1: Result | K1: Redmine Defect | L1: Additional/Comments/Issues | M1: QA PIC | N1: =SUM(N2:N118) -> 100 | O1: =SUM(O2:O118) -> 0 | P1: =SUM(P2:P118) -> 0 | Q1: =SUM(Q2:Q118) -> 0 | R1: =SUM(R2:R118) -> 0
A2: Pendaftaran Pengguna Baharu | N2: =COUNTIF($J3:J67,"PASS") -> 65 | O2: =COUNTIF($J3:J67,"FAIL") -> 0 | P2: =COUNTBLANK(J3:J67) -> 0 | Q2: =COUNTIF($J3:J67,"IN PROGRESS") -> 0 | R2: =COUNTIF($J3:J67,"BLOCKED") -> 0
